<?xml version="1.0" ?>
<!-- =================================================================================== -->
<!-- |    This document was autogenerated by xacro from pendulum.xacro                 | -->
<!-- |    EDITING THIS FILE BY HAND IS NOT RECOMMENDED                                 | -->
<!-- =================================================================================== -->
<robot name="pendulum" xmlns:xacro="http://ros.org/wiki/xacro">
  <material name="omni/Blue">
    <color rgba="0 0 0.8 1"/>
  </material>
  <material name="omni/Red">
    <color rgba="1 0 0 1"/>
  </material>
  <material name="omni/White">
    <color rgba="1 1 1 1"/>
  </material>
  <material name="omni/Green">
    <color rgba="0 1 0 1"/>
  </material>
  <material name="omni/Yellow">
    <color rgba="1 1 0 1"/>
  </material>
  <material name="omni/LightGrey">
    <color rgba="0.6 0.6 0.6 1"/>
  </material>
  <material name="omni/DarkGrey">
    <color rgba="0.4 0.4 0.4 1"/>
  </material>
  <link name="base_link">    
    </link>
  <link name="visual_joint">
    <visual>
      <origin rpy="0 1.57 0" xyz="0 0 0"/>
      <geometry>
        <cylinder length="0.1" radius="0.05"/>
      </geometry>
      <material name="omni/Blue"/>
    </visual>
  </link>
  <link name="pendulum">
    <visual>
      <origin rpy="0 0 0" xyz="0 0 -0.5"/>
      <geometry>
        <box size="0.0166666666667 0.0166666666667 1.0"/>
      </geometry>
      <material name="omni/Red"/>
    </visual>
    <collision>
      <origin rpy="0 0 0" xyz="0 0 -0.5"/>
      <geometry>
        <!-- <box size="${width} ${width} ${length}"/> -->
        <box size="0.0166666666667 0.0166666666667 1.0"/>
      </geometry>
    </collision>
    <inertial>
      <!-- CENTER OF MASS -->
      <origin rpy="0 0 0" xyz="0 0 -0.5"/>
      <mass value="1.0"/>
      <!-- box inertia: 1/12*m(y^2+z^2), ... -->
      <inertia ixx="0.0833564814815" ixy="0" ixz="0" iyy="0.0833564814815" iyz="0" izz="4.62962962963e-05"/>
    </inertial>
  </link>
  <joint name="base2pendulum_joint" type="revolute">
    <origin rpy="0 0 0" xyz="0 0 1.3"/>
    <parent link="base_link"/>
    <child link="pendulum"/>
    <dynamics damping="0.1" friction="0.0"/>
    <limit effort="2" lower="-20" upper="20" velocity="10.0"/>
    <axis xyz="1 0 0"/>
  </joint>
  <joint name="base2visualJoint_joint" type="fixed">
    <origin rpy="0 0 0" xyz="0 0 1.3"/>
    <parent link="base_link"/>
    <child link="visual_joint"/>
  </joint>
</robot>

